Neste caso o management host eh esse aqui: se nao for, alterar o ip management host aqui!
Monitoramento iniciado: host 172.16.1.30!
4_6_172.16.2.30_172.16.1.30_48034_5001 1745259094 1514
4_6_172.16.2.30_172.16.1.30_48034_5001 1745259094 2962
4_6_172.16.2.30_172.16.1.30_48034_5001 1745259094 5858
4_6_172.16.2.30_172.16.1.30_48034_5001 1745259094 2962
4_6_172.16.2.30_172.16.1.30_48034_5001 1745259094 8754
4_6_172.16.2.30_172.16.1.30_48034_5001 1745259094 5858
4_6_172.16.2.30_172.16.1.30_48034_5001 1745259094 1514
4_6_172.16.2.30_172.16.1.30_48034_5001 1745259094 15994
4_6_172.16.2.30_172.16.1.30_48034_5001 1745259094 5858
4_6_172.16.2.30_172.16.1.30_48034_5001 1745259094 5858
4_6_172.16.2.30_172.16.1.30_48034_5001 1745259094 2962
4_6_172.16.2.30_172.16.1.30_48034_5001 1745259094 23234
4_6_172.16.2.30_172.16.1.30_48034_5001 1745259094 8754
4_6_172.16.2.30_172.16.1.30_48034_5001 1745259094 2962
4_6_172.16.2.30_172.16.1.30_48034_5001 1745259094 8754
4_6_172.16.2.30_172.16.1.30_48034_5001 1745259094 7306
4_6_172.16.2.30_172.16.1.30_48034_5001 1745259094 2962
4_6_172.16.2.30_172.16.1.30_48034_5001 1745259094 24682
4_6_172.16.2.30_172.16.1.30_48034_5001 1745259094 8754
4_6_172.16.2.30_172.16.1.30_48034_5001 1745259094 2962
enviando monitoring tempo:  1745259094276
Enviando flowmonitoring para %s:%d 172.16.1.30 9090
Enviando msg_str para -> 172.16.1.30:9090

4_6_172.16.2.30_172.16.1.30_48034_5001 1745259094 10202
4_6_172.16.2.30_172.16.1.30_48034_5001 1745259094 10202
4_6_172.16.2.30_172.16.1.30_48034_5001 1745259094 24682
Exception in thread Thread-1:
Traceback (most recent call last):
Traceback (most recent call last):
  File "/usr/local/lib/python3.8/threading.py", line 932, in _bootstrap_inner
  File "host/host_normal_server.py", line 48, in <module>
    self.run()
  File "/usr/local/lib/python3.8/threading.py", line 870, in run
    start_monitoring(ip_management_host=ip_management_host,port_management_host=PORT_MANAGEMENT_HOST,meu_ip=ip_management_host, interface=get_minha_interface())
  File "/home/nnmoc/host1/host/host_traffic_monitoring/monitoring_utils.py", line 245, in start_monitoring
    self._target(*self._args, **self._kwargs)
  File "/home/nnmoc/host1/host/host_traffic_monitoring/monitoring_utils.py", line 33, in enviar_msg
    tcp.connect((server_ip, server_port))
    nome_fluxo = str(ip_pkt.version) + "_"+ str(ip_pkt.proto) + "_"+ ip_pkt.src + "_"+ ip_pkt.dst + "_"+ str(ip_pkt.sport) + "_"+str(ip_pkt.dport)
AttributeError: 'NoneType' object has no attribute 'version'
OSError: [Errno 101] Network is unreachable
Neste caso o management host eh esse aqui: se nao for, alterar o ip management host aqui!
Monitoramento iniciado: host 172.16.1.30!
4_6_172.16.2.30_172.16.1.30_40192_5001 1745259641 1514
4_6_172.16.2.30_172.16.1.30_40192_5001 1745259641 1514
4_6_172.16.2.30_172.16.1.30_40192_5001 1745259641 1514
4_6_172.16.2.30_172.16.1.30_40192_5001 1745259641 2962
4_6_172.16.2.30_172.16.1.30_40192_5001 1745259641 2962
4_6_172.16.2.30_172.16.1.30_40192_5001 1745259641 2962
4_6_172.16.2.30_172.16.1.30_40192_5001 1745259641 2962
4_6_172.16.2.30_172.16.1.30_40192_5001 1745259641 2962
4_6_172.16.2.30_172.16.1.30_40192_5001 1745259641 2962
4_6_172.16.2.30_172.16.1.30_40192_5001 1745259641 2962
4_6_172.16.2.30_172.16.1.30_40192_5001 1745259641 2962
4_6_172.16.2.30_172.16.1.30_40192_5001 1745259641 2962
4_6_172.16.2.30_172.16.1.30_40192_5001 1745259641 2962
4_6_172.16.2.30_172.16.1.30_40192_5001 1745259641 2962
4_6_172.16.2.30_172.16.1.30_40192_5001 1745259641 2962
4_6_172.16.2.30_172.16.1.30_40192_5001 1745259641 2962
4_6_172.16.2.30_172.16.1.30_40192_5001 1745259641 2962
4_6_172.16.2.30_172.16.1.30_40192_5001 1745259641 4410
4_6_172.16.2.30_172.16.1.30_40192_5001 1745259641 4410
4_6_172.16.2.30_172.16.1.30_40192_5001 1745259641 1514
enviando monitoring tempo:  1745259641253
Enviando flowmonitoring para %s:%d 172.16.1.30 9090
Enviando msg_str para -> 172.16.1.30:9090

4_6_172.16.2.30_172.16.1.30_40192_5001 1745259641 1514
4_6_172.16.2.30_172.16.1.30_40192_5001 1745259641 1514
Exception in thread Thread-1:
Traceback (most recent call last):
  File "/usr/local/lib/python3.8/threading.py", line 932, in _bootstrap_inner
Traceback (most recent call last):
  File "host/host_normal_server.py", line 48, in <module>
    self.run()
  File "/usr/local/lib/python3.8/threading.py", line 870, in run
    start_monitoring(ip_management_host=ip_management_host,port_management_host=PORT_MANAGEMENT_HOST,meu_ip=ip_management_host, interface=get_minha_interface())
  File "/home/nnmoc/host1/host/host_traffic_monitoring/monitoring_utils.py", line 245, in start_monitoring
    nome_fluxo = str(ip_pkt.version) + "_"+ str(ip_pkt.proto) + "_"+ ip_pkt.src + "_"+ ip_pkt.dst + "_"+ str(ip_pkt.sport) + "_"+str(ip_pkt.dport)
AttributeError: 'NoneType' object has no attribute 'version'
    self._target(*self._args, **self._kwargs)
  File "/home/nnmoc/host1/host/host_traffic_monitoring/monitoring_utils.py", line 33, in enviar_msg
    tcp.connect((server_ip, server_port))
OSError: [Errno 101] Network is unreachable
Neste caso o management host eh esse aqui: se nao for, alterar o ip management host aqui!
Monitoramento iniciado: host 172.16.1.30!
4_6_172.16.2.30_172.16.1.30_60116_5001 1745259812 1514
4_6_172.16.2.30_172.16.1.30_60116_5001 1745259812 1514
4_6_172.16.2.30_172.16.1.30_60116_5001 1745259812 1514
4_6_172.16.2.30_172.16.1.30_60116_5001 1745259812 2962
4_6_172.16.2.30_172.16.1.30_60116_5001 1745259812 2962
4_6_172.16.2.30_172.16.1.30_60116_5001 1745259812 2962
4_6_172.16.2.30_172.16.1.30_60116_5001 1745259812 2962
4_6_172.16.2.30_172.16.1.30_60116_5001 1745259812 2962
4_6_172.16.2.30_172.16.1.30_60116_5001 1745259812 2962
4_6_172.16.2.30_172.16.1.30_60116_5001 1745259812 2962
4_6_172.16.2.30_172.16.1.30_60116_5001 1745259812 2962
4_6_172.16.2.30_172.16.1.30_60116_5001 1745259812 2962
4_6_172.16.2.30_172.16.1.30_60116_5001 1745259812 2962
4_6_172.16.2.30_172.16.1.30_60116_5001 1745259812 2962
4_6_172.16.2.30_172.16.1.30_60116_5001 1745259812 2962
4_6_172.16.2.30_172.16.1.30_60116_5001 1745259812 2962
4_6_172.16.2.30_172.16.1.30_60116_5001 1745259812 2962
4_6_172.16.2.30_172.16.1.30_60116_5001 1745259812 2962
4_6_172.16.2.30_172.16.1.30_60116_5001 1745259812 2962
4_6_172.16.2.30_172.16.1.30_60116_5001 1745259812 2962
enviando monitoring tempo:  1745259812701
Enviando flowmonitoring para %s:%d 172.16.1.30 9090
Enviando msg_str para -> 172.16.1.30:9090

Traceback (most recent call last):
  File "host/host_normal_server.py", line 48, in <module>
Exception in thread Thread-1:
Traceback (most recent call last):
  File "/usr/local/lib/python3.8/threading.py", line 932, in _bootstrap_inner
    start_monitoring(ip_management_host=ip_management_host,port_management_host=PORT_MANAGEMENT_HOST,meu_ip=ip_management_host, interface=get_minha_interface())
  File "/home/nnmoc/host1/host/host_traffic_monitoring/monitoring_utils.py", line 245, in start_monitoring
    nome_fluxo = str(ip_pkt.version) + "_"+ str(ip_pkt.proto) + "_"+ ip_pkt.src + "_"+ ip_pkt.dst + "_"+ str(ip_pkt.sport) + "_"+str(ip_pkt.dport)
    self.run()
  File "/usr/local/lib/python3.8/threading.py", line 870, in run
AttributeError: 'NoneType' object has no attribute 'version'
    self._target(*self._args, **self._kwargs)
  File "/home/nnmoc/host1/host/host_traffic_monitoring/monitoring_utils.py", line 33, in enviar_msg
    tcp.connect((server_ip, server_port))
OSError: [Errno 101] Network is unreachable
